<?xml version="1.0" ?>
<!-- =================================================================================== -->
<!-- |    This document was autogenerated by xacro from astrobee.xacro                 | -->
<!-- |    EDITING THIS FILE BY HAND IS NOT RECOMMENDED                                 | -->
<!-- =================================================================================== -->
<!-- Copyright (c) 2017, United States Government, as represented by the     -->
<!-- Administrator of the National Aeronautics and Space Administration.     -->
<!--                                                                         -->
<!-- All rights reserved.                                                    -->
<!--                                                                         -->
<!-- The Astrobee platform is licensed under the Apache License, Version 2.0 -->
<!-- (the "License"); you may not use this file except in compliance with    -->
<!-- the License. You may obtain a copy of the License at                    -->
<!--                                                                         -->
<!--     http://www.apache.org/licenses/LICENSE-2.0                          -->
<!--                                                                         -->
<!-- Unless required by applicable law or agreed to in writing, software     -->
<!-- distributed under the License is distributed on an "AS IS" BASIS,       -->
<!-- WITHOUT WARRANTIES OR CONDITIONS OF ANY KIND, either express or         -->
<!-- implied. See the License for the specific language governing            -->
<!-- permissions and limitations under the License.                          -->
<robot name="astrobee">
  <!-- BASE GEOMETRY -->
  <link name="honey_body">
    <self_collide>false</self_collide>
    <!-- body -->
    <visual name="body_visual">
      <origin rpy="0 0 0" xyz="0 0 0"/>
      <geometry>
        <mesh filename="/home/dan/astrobee/src/description/media/astrobee_freeflyer/meshes/body.dae"/>
      </geometry>
    </visual>
    <collision name="body_collision">
      <origin rpy="0 0 0" xyz="-0.000794 0.000229 -0.003907"/>
      <geometry>
        <box size="0.290513 0.151942 0.281129"/>
      </geometry>
    </collision>
    <!-- port pmc -->
    <visual name="pmc_port_visual">
      <origin rpy="0 0 0" xyz="0 0 0"/>
      <geometry>
        <mesh filename="/home/dan/astrobee/src/description/media/astrobee_freeflyer/meshes/pmc.dae"/>
      </geometry>
    </visual>
    <visual name="pmc_port_bumper_visual">
      <origin rpy="0 0 0" xyz="0 0 0"/>
      <geometry>
        <mesh filename="/home/dan/astrobee/src/description/media/astrobee_freeflyer/meshes/pmc_bumper.dae"/>
      </geometry>
    </visual>
    <visual name="pmc_port_skin_visual">
      <origin rpy="0 0 0" xyz="0 0 0"/>
      <geometry>
        <mesh filename="/home/dan/astrobee/src/description/media/astrobee_freeflyer/meshes/pmc_skin_honey.dae"/>
      </geometry>
    </visual>
    <collision name="pmc_port_collision">
      <origin rpy="0 0 0" xyz="0 -0.117546 0"/>
      <geometry>
        <box size="0.319199 0.083962 0.319588"/>
      </geometry>
    </collision>
    <!-- starboard pmc -->
    <visual name="pmc_stbd_visual">
      <origin rpy="0 3.14 3.14" xyz="0 0 0"/>
      <geometry>
        <mesh filename="/home/dan/astrobee/src/description/media/astrobee_freeflyer/meshes/pmc.dae"/>
      </geometry>
    </visual>
    <visual name="pmc_stbd_bumper_visual">
      <origin rpy="0 3.14 3.14" xyz="0 0 0"/>
      <geometry>
        <mesh filename="/home/dan/astrobee/src/description/media/astrobee_freeflyer/meshes/pmc_bumper.dae"/>
      </geometry>
    </visual>
    <visual name="pmc_stbd_skin_visual">
      <origin rpy="0 3.14 3.14" xyz="0 0 0"/>
      <geometry>
        <mesh filename="/home/dan/astrobee/src/description/media/astrobee_freeflyer/meshes/pmc_skin_honey.dae"/>
      </geometry>
    </visual>
    <collision name="pmc_stbd_collision">
      <origin rpy="0 0 0" xyz="0 0.117546 0"/>
      <geometry>
        <box size="0.319199 0.083962 0.319588"/>
      </geometry>
    </collision>
  </link>
  <!-- This is a workaround for KDL -->
  <link name="honey_inertial_link">
    <self_collide>false</self_collide>
    <inertial>
      <mass value="9.0877"/>
      <origin xyz="0 0 0"/>
      <inertia ixx="0.1454" ixy="0.0" ixz="0.0" iyy="0.1366" iyz="0.0" izz="0.1594"/>
    </inertial>
  </link>
  <joint name="inertial_joint" type="fixed">
    <origin rpy="0 0 0" xyz="0 0 0"/>
    <parent link="honey_body"/>
    <child link="honey_inertial_link"/>
  </joint>
  <gazebo>
    <plugin filename="libgazebo_model_plugin_drag.so" name="drag_ros">
      &gt;
      
      <namespace>/honey/</namespace>
      <coefficient>1.05</coefficient>
      <!-- Drag coefficient -->
      <area>0.092903</area>
      <!-- Surface area     -->
      <density>1.225</density>
      <!-- Air density      -->
    </plugin>
  </gazebo>
  <gazebo>
    <plugin filename="libgazebo_model_plugin_pmc.so" name="pmc_ros">
      <namespace>/honey/</namespace>
      <rate>62.5</rate>
      <bypass_blower_model>false</bypass_blower_model>
    </plugin>
  </gazebo>
  <gazebo>
    <plugin filename="libgazebo_model_plugin_eps.so" name="eps_ros">
      &gt;
      
      <namespace>/honey/</namespace>
      <rate>10.0</rate>
      <!-- Rate at which dock state checked  -->
      <distance_near>0.04</distance_near>
      <!-- Threshold distance for magnetism  -->
      <distance_far>0.05</distance_far>
      <!-- Threshold distance for magnetism  -->
      <delay>5.0</delay>
      <!-- Delay between contact and docking -->
      <battery_top_left>true</battery_top_left>
      <battery_top_right>true</battery_top_right>
      <battery_bottom_left>false</battery_bottom_left>
      <battery_bottom_right>false</battery_bottom_right>
    </plugin>
  </gazebo>
  <gazebo>
    <plugin filename="libgazebo_model_plugin_truth.so" name="truth_ros">
      <namespace>/honey/</namespace>
      <rate>62.5</rate>
      <parent>world</parent>
      <child>truth</child>
      <tf>true</tf>
      <pose>true</pose>
      <twist>true</twist>
      <static>false</static>
    </plugin>
  </gazebo>
  <gazebo>
    <plugin filename="libgazebo_model_plugin_laser.so" name="laser_ros">
      <namespace>/honey/</namespace>
      <rate>10.0</rate>
      <range>5.0</range>
      <width>0.0025</width>
    </plugin>
  </gazebo>
  <gazebo>
    <plugin filename="libgazebo_model_plugin_flashlight.so" name="flashlight_front_ros">
      <namespace>/honey/</namespace>
      <plugin_name>flashlight_front</plugin_name>
      <plugin_frame>flashlight_front</plugin_frame>
      <rate>10.0</rate>
      <width>0.02</width>
      <height>0.02</height>
      <depth>0.03</depth>
    </plugin>
    <plugin filename="libgazebo_model_plugin_flashlight.so" name="flashlight_aft_ros">
      <namespace>/honey/</namespace>
      <plugin_name>flashlight_aft</plugin_name>
      <plugin_frame>flashlight_aft</plugin_frame>
      <rate>10.0</rate>
      <width>0.02</width>
      <height>0.02</height>
      <depth>0.03</depth>
    </plugin>
  </gazebo>
  <gazebo>
    <plugin filename="libgazebo_model_plugin_speed_cam.so" name="speed_cam_ros">
      <namespace>/honey/</namespace>
    </plugin>
  </gazebo>
  <gazebo>
    <plugin filename="libgazebo_model_plugin_signal_lights.so" name="signal_lights_ros">
      <namespace>/honey/</namespace>
    </plugin>
  </gazebo>
  <gazebo>
    <plugin filename="libgazebo_model_plugin_llp_disk_monitor.so" name="llp_disk_monitor">
      <namespace>/honey/</namespace>
    </plugin>
    <plugin filename="libgazebo_model_plugin_llp_cpu_mem_monitor.so" name="llp_cpu_mem_monitor">
      <namespace>/honey/</namespace>
    </plugin>
    <plugin filename="libgazebo_model_plugin_mlp_disk_monitor.so" name="mlp_disk_monitor">
      <namespace>/honey/</namespace>
    </plugin>
    <plugin filename="libgazebo_model_plugin_mlp_cpu_mem_monitor.so" name="mlp_cpu_mem_monitor">
      <namespace>/honey/</namespace>
    </plugin>
  </gazebo>
  <gazebo reference="honey_body">
    <sensor name="imu" type="imu">
      <pose>0 0 0 0 0 0</pose>
      <always_on>true</always_on>
      <update_rate>62.5</update_rate>
      <visualize>0</visualize>
      <plugin filename="libgazebo_sensor_plugin_imu.so" name="sensor_imu_ros">
        <namespace>/honey/</namespace>
      </plugin>
    </sensor>
  </gazebo>
  <gazebo reference="honey_body">
    <sensor name="nav_cam" type="wideanglecamera">
      <pose>0 0 0 0 0 0</pose>
      <always_on>true</always_on>
      <update_rate>0.0001</update_rate>
      <camera>
        <horizontal_fov>2.957216683909311</horizontal_fov>
        <image>
          <width>320</width>
          <height>240</height>
          <format>L8</format>
        </image>
        <clip>
          <near>0.1</near>
          <far>20</far>
        </clip>
        <distortion>
          <k1>0.993308</k1>
        </distortion>
      </camera>
      <plugin filename="libgazebo_sensor_plugin_nav_cam.so" name="nav_cam_ros">
        <namespace>/honey/</namespace>
      </plugin>
      <plugin filename="libgazebo_sensor_plugin_sparse_map.so" name="sparse_map_ros">
        <namespace>/honey/</namespace>
      </plugin>
      <plugin filename="libgazebo_sensor_plugin_optical_flow.so" name="optical_flow_ros">
        <namespace>/honey/</namespace>
      </plugin>
    </sensor>
  </gazebo>
  <gazebo reference="honey_body">
    <sensor name="dock_cam" type="wideanglecamera">
      <pose>0 0 0 0 0 0</pose>
      <always_on>true</always_on>
      <update_rate>0.0001</update_rate>
      <camera>
        <horizontal_fov>2.87507641955055</horizontal_fov>
        <image>
          <width>320</width>
          <height>240</height>
          <format>L8</format>
        </image>
        <clip>
          <near>0.1</near>
          <far>20</far>
        </clip>
        <distortion>
          <k1>1.0049199133284734</k1>
        </distortion>
      </camera>
      <plugin filename="libgazebo_sensor_plugin_dock_cam.so" name="dock_cam_ros">
        <namespace>/honey/</namespace>
      </plugin>
      <plugin filename="libgazebo_sensor_plugin_ar_tags.so" name="ar_tags_ros">
        <namespace>/honey/</namespace>
      </plugin>
    </sensor>
  </gazebo>
  <gazebo reference="honey_body">
    <sensor name="haz_cam" type="depth">
      <pose>0 0 0 0 0 0</pose>
      <always_on>true</always_on>
      <update_rate>1</update_rate>
      <camera>
        <horizontal_fov>1.0821</horizontal_fov>
        <!-- 62 degrees -->
        <image>
          <width>224</width>
          <height>171</height>
          <format>L8</format>
        </image>
        <clip>
          <near>0.2</near>
          <far>4</far>
        </clip>
        <depth_camera>
          <output>points</output>
        </depth_camera>
      </camera>
      <plugin filename="libgazebo_sensor_plugin_haz_cam.so" name="haz_cam_ros">
        <namespace>/honey/</namespace>
      </plugin>
    </sensor>
  </gazebo>
  <gazebo reference="honey_body">
    <sensor name="perch_cam" type="depth">
      <pose>0 0 0 0 0 0</pose>
      <always_on>true</always_on>
      <update_rate>1</update_rate>
      <camera>
        <horizontal_fov>1.0821</horizontal_fov>
        <!-- 62 degrees -->
        <image>
          <width>224</width>
          <height>171</height>
          <format>L8</format>
        </image>
        <clip>
          <near>0.2</near>
          <far>4</far>
        </clip>
        <depth_camera>
          <output>points</output>
        </depth_camera>
      </camera>
      <plugin filename="libgazebo_sensor_plugin_perch_cam.so" name="perch_cam_ros">
        <namespace>/honey/</namespace>
      </plugin>
    </sensor>
  </gazebo>
  <link name="honey_top_aft">
    <self_collide>false</self_collide>
    <inertial>
      <origin rpy="0 0 0" xyz="0 0 0"/>
      <mass value="0.3078"/>
      <inertia ixx="0.02705" ixy="0.0" ixz="0.0" iyy="0.02705" iyz="0.0" izz="0.02705"/>
    </inertial>
    <visual>
      <origin rpy="0 0 0" xyz="0 0 0"/>
      <geometry>
        <mesh filename="/home/dan/astrobee/src/description/media/astrobee_freeflyer/meshes/base_link.dae"/>
      </geometry>
    </visual>
    <collision>
      <origin rpy="0 0 0" xyz="0 -0.038125 0"/>
      <geometry>
        <box size="0.090441 0.152400 0.076250"/>
      </geometry>
    </collision>
  </link>
  <joint name="top_aft" type="fixed">
    <origin rpy="0.0 3.1415 0.0" xyz="-0.01 0.0 -0.065"/>
    <parent link="honey_body"/>
    <child link="honey_top_aft"/>
  </joint>
  <link name="honey_top_aft_arm_proximal_link">
    <self_collide>false</self_collide>
    <inertial>
      <origin rpy="0 0 0" xyz="0 0 0"/>
      <mass value="0.1623"/>
      <inertia ixx="0.02705" ixy="0.0" ixz="0.0" iyy="0.02705" iyz="0.0" izz="0.02705"/>
    </inertial>
    <visual>
      <origin rpy="0 0 0" xyz="0 0 0"/>
      <geometry>
        <mesh filename="/home/dan/astrobee/src/description/media/astrobee_freeflyer/meshes/arm_proximal_link.dae"/>
      </geometry>
    </visual>
    <collision>
      <origin rpy="0 0 0" xyz="-0.049625 -0.0022 0"/>
      <geometry>
        <box size="0.123250 0.068000 0.042400"/>
      </geometry>
    </collision>
  </link>
  <joint name="top_aft_arm_proximal_joint" type="revolute">
    <origin rpy="0 1.57079632679 0" xyz="0.11945 0 0.065"/>
    <parent link="honey_top_aft"/>
    <child link="honey_top_aft_arm_proximal_link"/>
    <axis xyz="0 -1 0"/>
    <limit effort="1.0" lower="-2.0944" upper="1.57079" velocity="0.12"/>
  </joint>
  <link name="honey_top_aft_arm_distal_link">
    <self_collide>false</self_collide>
    <inertial>
      <origin rpy="0 0 0" xyz="0 0 0"/>
      <mass value="0.1033"/>
      <inertia ixx="0.002705" ixy="0.0" ixz="0.0" iyy="0.002705" iyz="0.0" izz="0.002705"/>
    </inertial>
    <visual>
      <origin rpy="0 0 0" xyz="0 0 0"/>
      <geometry>
        <mesh filename="/home/dan/astrobee/src/description/media/astrobee_freeflyer/meshes/arm_distal_link.dae"/>
      </geometry>
    </visual>
    <collision>
      <origin rpy="0 0 0" xyz="0 0 -0.02"/>
      <geometry>
        <box size="0.075000 0.070000 0.087400"/>
      </geometry>
    </collision>
  </link>
  <joint name="top_aft_arm_distal_joint" type="revolute">
    <origin rpy="0 0 0" xyz="-0.1 0 0"/>
    <parent link="honey_top_aft_arm_proximal_link"/>
    <child link="honey_top_aft_arm_distal_link"/>
    <axis xyz="0 0 1"/>
    <limit effort="1.0" lower="-1.57079" upper="1.57079" velocity="0.12"/>
  </joint>
  <link name="honey_top_aft_gripper_left_proximal_link">
    <self_collide>false</self_collide>
    <inertial>
      <origin rpy="0 0 0" xyz="0 0 0"/>
      <mass value="0.04"/>
      <inertia ixx="0.002705" ixy="0.0" ixz="0.0" iyy="0.002705" iyz="0.0" izz="0.002705"/>
    </inertial>
    <visual>
      <origin rpy="0 0 0" xyz="0 0 0"/>
      <geometry>
        <mesh filename="/home/dan/astrobee/src/description/media/astrobee_freeflyer/meshes/gripper_left_proximal_link.dae"/>
      </geometry>
    </visual>
    <collision>
      <origin rpy="0 0 0" xyz="-0.025547 0 -0.000875"/>
      <geometry>
        <box size="0.067654 0.021750 0.025400"/>
      </geometry>
    </collision>
  </link>
  <joint name="top_aft_gripper_left_proximal_joint" type="revolute">
    <origin rpy="0 0 0" xyz="-0.039 -0.010002 -0.0497"/>
    <parent link="honey_top_aft_arm_distal_link"/>
    <child link="honey_top_aft_gripper_left_proximal_link"/>
    <axis xyz="0 0 1"/>
    <limit effort="0.1" lower="0.349066" upper="0.698132" velocity="0.12"/>
  </joint>
  <link name="honey_top_aft_gripper_left_distal_link">
    <self_collide>false</self_collide>
    <inertial>
      <origin rpy="0 0 0" xyz="0 0 0"/>
      <mass value="0.0116026396896178"/>
      <inertia ixx="0.002705" ixy="0.0" ixz="0.0" iyy="0.002705" iyz="0.0" izz="0.002705"/>
    </inertial>
    <visual>
      <origin rpy="0 0 0" xyz="0 0 0"/>
      <geometry>
        <mesh filename="/home/dan/astrobee/src/description/media/astrobee_freeflyer/meshes/gripper_left_distal_link.dae"/>
      </geometry>
    </visual>
    <collision>
      <origin rpy="0 0 0" xyz="-0.021524 0 -0.000875"/>
      <geometry>
        <box size="0.056953 0.021750 0.025400"/>
      </geometry>
    </collision>
  </link>
  <joint name="top_aft_gripper_left_distal_joint" type="revolute">
    <origin rpy="0 0 0" xyz="-0.05 0 0"/>
    <parent link="honey_top_aft_gripper_left_proximal_link"/>
    <child link="honey_top_aft_gripper_left_distal_link"/>
    <axis xyz="0 0 1"/>
    <limit effort="0.1" lower="-1.22173" upper="-0.69813" velocity="0.12"/>
  </joint>
  <link name="honey_top_aft_gripper_right_proximal_link">
    <self_collide>false</self_collide>
    <inertial>
      <origin rpy="0 0 0" xyz="0 0 0"/>
      <mass value="0.04"/>
      <inertia ixx="0.002705" ixy="0.0" ixz="0.0" iyy="0.002705" iyz="0.0" izz="0.002705"/>
    </inertial>
    <visual>
      <origin rpy="0 0 0" xyz="0 0 0"/>
      <geometry>
        <mesh filename="/home/dan/astrobee/src/description/media/astrobee_freeflyer/meshes/gripper_right_proximal_link.dae"/>
      </geometry>
    </visual>
    <collision>
      <origin rpy="0 0 0" xyz="-0.025547 0 0.000875"/>
      <geometry>
        <box size="0.067654 0.021750 0.025400"/>
      </geometry>
    </collision>
  </link>
  <joint name="top_aft_gripper_right_proximal_joint" type="revolute">
    <origin rpy="0 0 0" xyz="-0.039 0.010002 -0.0497"/>
    <parent link="honey_top_aft_arm_distal_link"/>
    <child link="honey_top_aft_gripper_right_proximal_link"/>
    <axis xyz="0 0 1"/>
    <limit effort="0.1" lower="-0.698132" upper="-0.349066" velocity="0.12"/>
  </joint>
  <link name="honey_top_aft_gripper_right_distal_link">
    <self_collide>false</self_collide>
    <inertial>
      <origin rpy="0 0 0" xyz="0 0 0"/>
      <mass value="0.02285"/>
      <inertia ixx="0.002705" ixy="0.0" ixz="0.0" iyy="0.002705" iyz="0.0" izz="0.002705"/>
    </inertial>
    <visual>
      <origin rpy="0 0 0" xyz="0 0 0"/>
      <geometry>
        <mesh filename="/home/dan/astrobee/src/description/media/astrobee_freeflyer/meshes/gripper_right_distal_link.dae"/>
      </geometry>
    </visual>
    <collision>
      <origin rpy="0 0 0" xyz="-0.021512 0 0.000875"/>
      <geometry>
        <box size="0.056894 0.021750 0.025400"/>
      </geometry>
    </collision>
  </link>
  <joint name="top_aft_gripper_right_distal_joint" type="revolute">
    <origin rpy="0 0 0" xyz="-0.05 0 0"/>
    <parent link="honey_top_aft_gripper_right_proximal_link"/>
    <child link="honey_top_aft_gripper_right_distal_link"/>
    <axis xyz="0 0 1"/>
    <limit effort="0.1" lower="0.69813" upper="1.22173" velocity="0.12"/>
  </joint>
  <gazebo>
    <plugin filename="libgazebo_model_plugin_perching_arm.so" name="top_aft_perching_arm_ros">
      &gt;
        
      <namespace>/honey/</namespace>
      <rate>10.0</rate>
      <bay>top_aft</bay>
      <proximal>1.57079632679</proximal>
      <distal>0</distal>
      <gripper>0</gripper>
    </plugin>
  </gazebo>
</robot>

