<mujoco model="astrobee">
  <compiler angle="radian" autolimits="true"/>
  <default/>

  <!-- My stuff -->
  <asset>
    <!-- Grid texture for floor -->
    <texture name="grid" type="2d" builtin="checker" width="512" height="512" rgb2="0 0 0" rgb1="1 1 1"/>
    <material name="grid" texture="grid" texrepeat="2 2" texuniform="true" reflectance=".6"/>
    <!-- Sponge texture for the cube -->
    <texture name="texsponge" type="2d" file="sponge.png"/>
    <material name="matsponge" texture="texsponge" specular="0.3"/>
  </asset>

  <worldbody>
    <!-- Adding a floor and some lighting -->
    <geom name="floor" size="0 0 .05" type="plane" material="grid" condim="3" pos="0 0 -1" />
    <light name="top" pos="0 0 2"/>

    <!-- My changes to the autogenerated mjcf: stuck everything within a single body tag, and added a freejoint -->
    <body name="astrobee_body" pos="0 0 0" gravcomp="0">
      <freejoint/>
      <geom size="0.145257 0.075971 0.140565" pos="-0.000794 0.000229 -0.003907" type="box"/>
      <geom size="0.1596 0.041981 0.159794" pos="0 -0.117546 0" type="box"/>
      <geom size="0.1596 0.041981 0.159794" pos="0 0.117546 0" type="box"/>
      <geom size="0.0452205 0.0762 0.038125" pos="-0.01 -0.038125 -0.065" quat="4.63268e-05 0 1 0" type="box"/>
      <body name="honey_top_aft_arm_proximal_link" pos="-0.129444 0 -0.130011" quat="-0.707074 0 0.70714 0" gravcomp="0">
        <inertial pos="0 0 0" mass="0.1623" diaginertia="0.02705 0.02705 0.02705"/>
        <joint name="top_aft_arm_proximal_joint" pos="0 0 0" axis="0 -1 0" range="-2.0944 1.57079"/>
        <geom size="0.061625 0.034 0.0212" pos="-0.049625 -0.0022 0" type="box"/>
        <body name="honey_top_aft_arm_distal_link" pos="-0.1 0 0" gravcomp="0">
          <inertial pos="0 0 0" mass="0.1033" diaginertia="0.002705 0.002705 0.002705"/>
          <joint name="top_aft_arm_distal_joint" pos="0 0 0" axis="0 0 1" range="-1.57079 1.57079"/>
          <geom size="0.0375 0.035 0.0437" pos="0 0 -0.02" type="box"/>
          <body name="honey_top_aft_gripper_left_proximal_link" pos="-0.039 -0.010002 -0.0497" gravcomp="0">
            <inertial pos="0 0 0" mass="0.04" diaginertia="0.002705 0.002705 0.002705"/>
            <joint name="top_aft_gripper_left_proximal_joint" pos="0 0 0" axis="0 0 1" range="0.349066 0.698132"/>
            <geom size="0.033827 0.010875 0.0127" pos="-0.025547 0 -0.000875" type="box"/>
            <body name="honey_top_aft_gripper_left_distal_link" pos="-0.05 0 0" gravcomp="0">
              <inertial pos="0 0 0" mass="0.0116026" diaginertia="0.002705 0.002705 0.002705"/>
              <joint name="top_aft_gripper_left_distal_joint" pos="0 0 0" axis="0 0 1" range="-1.22173 -0.69813"/>
              <geom size="0.0284765 0.010875 0.0127" pos="-0.021524 0 -0.000875" type="box"/>
            </body>
          </body>
          <body name="honey_top_aft_gripper_right_proximal_link" pos="-0.039 0.010002 -0.0497" gravcomp="0">
            <inertial pos="0 0 0" mass="0.04" diaginertia="0.002705 0.002705 0.002705"/>
            <joint name="top_aft_gripper_right_proximal_joint" pos="0 0 0" axis="0 0 1" range="-0.698132 -0.349066"/>
            <geom size="0.033827 0.010875 0.0127" pos="-0.025547 0 0.000875" type="box"/>
            <body name="honey_top_aft_gripper_right_distal_link" pos="-0.05 0 0" gravcomp="0">
              <inertial pos="0 0 0" mass="0.02285" diaginertia="0.002705 0.002705 0.002705"/>
              <joint name="top_aft_gripper_right_distal_joint" pos="0 0 0" axis="0 0 1" range="0.69813 1.22173"/>
              <geom size="0.028447 0.010875 0.0127" pos="-0.021512 0 0.000875" type="box"/>
            </body>
          </body>
        </body>
      </body>
    </body>
  </worldbody>
</mujoco>
