<?xml version="1.0" ?>
<robot name="astrobee">
  <!-- BASE GEOMETRY -->
  <link name="honey_body">
    <self_collide>false</self_collide>
    <!-- body -->
    <visual name="body_visual">
      <origin rpy="0 0 0" xyz="0 0 0"/>
      <geometry>
        <mesh filename="/home/dan/astrobee/src/description/media/astrobee_freeflyer/meshes/body.dae"/>
      </geometry>
    </visual>
    <collision name="body_collision">
      <origin rpy="0 0 0" xyz="-0.000794 0.000229 -0.003907"/>
      <geometry>
        <box size="0.290513 0.151942 0.281129"/>
      </geometry>
    </collision>
    <inertial> 
      <mass value="9.0877"/>
      <origin xyz="0 0 0"/>
      <inertia ixx="0.1454" ixy="0.0" ixz="0.0" iyy="0.1366" iyz="0.0" izz="0.1594"/>
    </inertial>
    <!-- port pmc -->
    <visual name="pmc_port_visual">
      <origin rpy="0 0 0" xyz="0 0 0"/>
      <geometry>
        <mesh filename="/home/dan/astrobee/src/description/media/astrobee_freeflyer/meshes/pmc.dae"/>
      </geometry>
    </visual>
    <visual name="pmc_port_bumper_visual">
      <origin rpy="0 0 0" xyz="0 0 0"/>
      <geometry>
        <mesh filename="/home/dan/astrobee/src/description/media/astrobee_freeflyer/meshes/pmc_bumper.dae"/>
      </geometry>
    </visual>
    <visual name="pmc_port_skin_visual">
      <origin rpy="0 0 0" xyz="0 0 0"/>
      <geometry>
        <mesh filename="/home/dan/astrobee/src/description/media/astrobee_freeflyer/meshes/pmc_skin_honey.dae"/>
      </geometry>
    </visual>
    <collision name="pmc_port_collision">
      <origin rpy="0 0 0" xyz="0 -0.117546 0"/>
      <geometry>
        <box size="0.319199 0.083962 0.319588"/>
      </geometry>
    </collision>
    <!-- starboard pmc -->
    <visual name="pmc_stbd_visual">
      <origin rpy="0 3.14 3.14" xyz="0 0 0"/>
      <geometry>
        <mesh filename="/home/dan/astrobee/src/description/media/astrobee_freeflyer/meshes/pmc.dae"/>
      </geometry>
    </visual>
    <visual name="pmc_stbd_bumper_visual">
      <origin rpy="0 3.14 3.14" xyz="0 0 0"/>
      <geometry>
        <mesh filename="/home/dan/astrobee/src/description/media/astrobee_freeflyer/meshes/pmc_bumper.dae"/>
      </geometry>
    </visual>
    <visual name="pmc_stbd_skin_visual">
      <origin rpy="0 3.14 3.14" xyz="0 0 0"/>
      <geometry>
        <mesh filename="/home/dan/astrobee/src/description/media/astrobee_freeflyer/meshes/pmc_skin_honey.dae"/>
      </geometry>
    </visual>
    <collision name="pmc_stbd_collision">
      <origin rpy="0 0 0" xyz="0 0.117546 0"/>
      <geometry>
        <box size="0.319199 0.083962 0.319588"/>
      </geometry>
    </collision>
  </link>
  <link name="honey_top_aft">
    <self_collide>false</self_collide>
    <inertial>
      <origin rpy="0 0 0" xyz="0 0 0"/>
      <mass value="0.3078"/>
      <inertia ixx="0.02705" ixy="0.0" ixz="0.0" iyy="0.02705" iyz="0.0" izz="0.02705"/>
    </inertial>
    <visual>
      <origin rpy="0 0 0" xyz="0 0 0"/>
      <geometry>
        <mesh filename="/home/dan/astrobee/src/description/media/astrobee_freeflyer/meshes/base_link.dae"/>
      </geometry>
    </visual>
    <collision>
      <origin rpy="0 0 0" xyz="0 -0.038125 0"/>
      <geometry>
        <box size="0.090441 0.152400 0.076250"/>
      </geometry>
    </collision>
  </link>
  <joint name="top_aft" type="fixed">
    <origin rpy="0.0 3.1415 0.0" xyz="-0.01 0.0 -0.065"/>
    <parent link="honey_body"/>
    <child link="honey_top_aft"/>
  </joint>
  <link name="honey_top_aft_arm_proximal_link">
    <self_collide>false</self_collide>
    <inertial>
      <origin rpy="0 0 0" xyz="0 0 0"/>
      <mass value="0.1623"/>
      <inertia ixx="0.02705" ixy="0.0" ixz="0.0" iyy="0.02705" iyz="0.0" izz="0.02705"/>
    </inertial>
    <visual>
      <origin rpy="0 0 0" xyz="0 0 0"/>
      <geometry>
        <mesh filename="/home/dan/astrobee/src/description/media/astrobee_freeflyer/meshes/arm_proximal_link.dae"/>
      </geometry>
    </visual>
    <collision>
      <origin rpy="0 0 0" xyz="-0.049625 -0.0022 0"/>
      <geometry>
        <box size="0.123250 0.068000 0.042400"/>
      </geometry>
    </collision>
  </link>
  <joint name="top_aft_arm_proximal_joint" type="revolute">
    <origin rpy="0 1.57079632679 0" xyz="0.11945 0 0.065"/>
    <parent link="honey_top_aft"/>
    <child link="honey_top_aft_arm_proximal_link"/>
    <axis xyz="0 -1 0"/>
    <limit effort="1.0" lower="-2.0944" upper="1.57079" velocity="0.12"/>
  </joint>
  <link name="honey_top_aft_arm_distal_link">
    <self_collide>false</self_collide>
    <inertial>
      <origin rpy="0 0 0" xyz="0 0 0"/>
      <mass value="0.1033"/>
      <inertia ixx="0.002705" ixy="0.0" ixz="0.0" iyy="0.002705" iyz="0.0" izz="0.002705"/>
    </inertial>
    <visual>
      <origin rpy="0 0 0" xyz="0 0 0"/>
      <geometry>
        <mesh filename="/home/dan/astrobee/src/description/media/astrobee_freeflyer/meshes/arm_distal_link.dae"/>
      </geometry>
    </visual>
    <collision>
      <origin rpy="0 0 0" xyz="0 0 -0.02"/>
      <geometry>
        <box size="0.075000 0.070000 0.087400"/>
      </geometry>
    </collision>
  </link>
  <joint name="top_aft_arm_distal_joint" type="revolute">
    <origin rpy="0 0 0" xyz="-0.1 0 0"/>
    <parent link="honey_top_aft_arm_proximal_link"/>
    <child link="honey_top_aft_arm_distal_link"/>
    <axis xyz="0 0 1"/>
    <limit effort="1.0" lower="-1.57079" upper="1.57079" velocity="0.12"/>
  </joint>
  <link name="honey_top_aft_gripper_left_proximal_link">
    <self_collide>false</self_collide>
    <inertial>
      <origin rpy="0 0 0" xyz="0 0 0"/>
      <mass value="0.04"/>
      <inertia ixx="0.002705" ixy="0.0" ixz="0.0" iyy="0.002705" iyz="0.0" izz="0.002705"/>
    </inertial>
    <visual>
      <origin rpy="0 0 0" xyz="0 0 0"/>
      <geometry>
        <mesh filename="/home/dan/astrobee/src/description/media/astrobee_freeflyer/meshes/gripper_left_proximal_link.dae"/>
      </geometry>
    </visual>
    <collision>
      <origin rpy="0 0 0" xyz="-0.025547 0 -0.000875"/>
      <geometry>
        <box size="0.067654 0.021750 0.025400"/>
      </geometry>
    </collision>
  </link>
  <joint name="top_aft_gripper_left_proximal_joint" type="revolute">
    <origin rpy="0 0 0" xyz="-0.039 -0.010002 -0.0497"/>
    <parent link="honey_top_aft_arm_distal_link"/>
    <child link="honey_top_aft_gripper_left_proximal_link"/>
    <axis xyz="0 0 1"/>
    <limit effort="0.1" lower="0.349066" upper="0.698132" velocity="0.12"/>
  </joint>
  <link name="honey_top_aft_gripper_left_distal_link">
    <self_collide>false</self_collide>
    <inertial>
      <origin rpy="0 0 0" xyz="0 0 0"/>
      <mass value="0.0116026396896178"/>
      <inertia ixx="0.002705" ixy="0.0" ixz="0.0" iyy="0.002705" iyz="0.0" izz="0.002705"/>
    </inertial>
    <visual>
      <origin rpy="0 0 0" xyz="0 0 0"/>
      <geometry>
        <mesh filename="/home/dan/astrobee/src/description/media/astrobee_freeflyer/meshes/gripper_left_distal_link.dae"/>
      </geometry>
    </visual>
    <collision>
      <origin rpy="0 0 0" xyz="-0.021524 0 -0.000875"/>
      <geometry>
        <box size="0.056953 0.021750 0.025400"/>
      </geometry>
    </collision>
  </link>
  <joint name="top_aft_gripper_left_distal_joint" type="revolute">
    <origin rpy="0 0 0" xyz="-0.05 0 0"/>
    <parent link="honey_top_aft_gripper_left_proximal_link"/>
    <child link="honey_top_aft_gripper_left_distal_link"/>
    <axis xyz="0 0 1"/>
    <limit effort="0.1" lower="-1.22173" upper="-0.69813" velocity="0.12"/>
  </joint>
  <link name="honey_top_aft_gripper_right_proximal_link">
    <self_collide>false</self_collide>
    <inertial>
      <origin rpy="0 0 0" xyz="0 0 0"/>
      <mass value="0.04"/>
      <inertia ixx="0.002705" ixy="0.0" ixz="0.0" iyy="0.002705" iyz="0.0" izz="0.002705"/>
    </inertial>
    <visual>
      <origin rpy="0 0 0" xyz="0 0 0"/>
      <geometry>
        <mesh filename="/home/dan/astrobee/src/description/media/astrobee_freeflyer/meshes/gripper_right_proximal_link.dae"/>
      </geometry>
    </visual>
    <collision>
      <origin rpy="0 0 0" xyz="-0.025547 0 0.000875"/>
      <geometry>
        <box size="0.067654 0.021750 0.025400"/>
      </geometry>
    </collision>
  </link>
  <joint name="top_aft_gripper_right_proximal_joint" type="revolute">
    <origin rpy="0 0 0" xyz="-0.039 0.010002 -0.0497"/>
    <parent link="honey_top_aft_arm_distal_link"/>
    <child link="honey_top_aft_gripper_right_proximal_link"/>
    <axis xyz="0 0 1"/>
    <limit effort="0.1" lower="-0.698132" upper="-0.349066" velocity="0.12"/>
  </joint>
  <link name="honey_top_aft_gripper_right_distal_link">
    <self_collide>false</self_collide>
    <inertial>
      <origin rpy="0 0 0" xyz="0 0 0"/>
      <mass value="0.02285"/>
      <inertia ixx="0.002705" ixy="0.0" ixz="0.0" iyy="0.002705" iyz="0.0" izz="0.002705"/>
    </inertial>
    <visual>
      <origin rpy="0 0 0" xyz="0 0 0"/>
      <geometry>
        <mesh filename="/home/dan/astrobee/src/description/media/astrobee_freeflyer/meshes/gripper_right_distal_link.dae"/>
      </geometry>
    </visual>
    <collision>
      <origin rpy="0 0 0" xyz="-0.021512 0 0.000875"/>
      <geometry>
        <box size="0.056894 0.021750 0.025400"/>
      </geometry>
    </collision>
  </link>
  <joint name="top_aft_gripper_right_distal_joint" type="revolute">
    <origin rpy="0 0 0" xyz="-0.05 0 0"/>
    <parent link="honey_top_aft_gripper_right_proximal_link"/>
    <child link="honey_top_aft_gripper_right_distal_link"/>
    <axis xyz="0 0 1"/>
    <limit effort="0.1" lower="0.69813" upper="1.22173" velocity="0.12"/>
  </joint>
</robot>

